<?xml version="1.0"?>
<!-- Describe URDF for PhantomX Pincher Arm -->
<robot name="phantomx_pincher_arm">

    <!-- the base 0-->
    <link name="base_footprint"/>
    <joint name="base_joint" type="fixed">
      <origin xyz="0 0 0.0102" rpy="0 0 0" />
      <parent link="base_footprint"/>
      <child link="base_link" />
    </joint>
    <link name="base_link">
      <visual>
        <geometry>
          <!-- new mesh -->
          <mesh filename="package://kobuki_description/meshes/main_body.dae" />
        </geometry>
        <origin xyz="0.001 0 0.05199" rpy="0 0 0"/>
      </visual>
      <collision name="base">
        <geometry>
          <cylinder length="0.10938" radius="0.178"/>
        </geometry>
        <origin xyz="0.0 0 0.05949" rpy="0 0 0"/>
      </collision>
      <inertial>
        <!-- COM experimentally determined -->
        <origin xyz="0.01 0 0"/>
        <mass value="2.4"/> 
        <inertia ixx="0.019995" ixy="0.0" ixz="0.0"
                 iyy="0.019995" iyz="0.0"
                 izz="0.03675" />
      </inertial>
    </link>

    <joint name="wheel_left_joint" type="continuous">
      <parent link="base_link"/>
      <child link="wheel_left_link"/>
      <origin xyz="0.00 .115 0.0250" rpy="-1.57 0 0"/>
      <axis xyz="0 0 1"/>
    </joint>
    <link name="wheel_left_link">
      <visual>
        <geometry>
          <mesh filename="package://kobuki_description/meshes/wheel.dae"/>
        </geometry>
        <origin xyz="0 0 0" rpy="0 0 0"/>
      </visual>
      <collision>
        <geometry>
          <cylinder length="0.0206" radius="0.0352"/>
        </geometry>
        <origin rpy="0 0 0" xyz="0 0 0"/>
      </collision>
      <inertial>
        <mass value="0.01" />
        <origin xyz="0 0 0" />
        <inertia ixx="0.001" ixy="0.0" ixz="0.0"
                 iyy="0.001" iyz="0.0"
                 izz="0.001" />
      </inertial>
    </link>

    <joint name="wheel_right_joint" type="continuous">
      <parent link="base_link"/>
      <child link="wheel_right_link"/>
      <origin xyz="0.00 -.115 0.0250" rpy="-1.57 0 0"/>
      <axis xyz="0 0 1"/>
    </joint>
    <link name="wheel_right_link">
      <visual>
        <geometry>
          <mesh filename="package://kobuki_description/meshes/wheel.dae"/>
        </geometry>
        <origin xyz="0 0 0" rpy="0 0 0"/>
      </visual>
      <collision>
        <geometry>
          <cylinder length="0.0206" radius="0.0350"/>
        </geometry>
        <origin rpy="0 0 0" xyz="0 0 0"/>
      </collision>
      <inertial>
        <mass value="0.01" />
        <origin xyz="0 0 0" />
        <inertia ixx="0.001" ixy="0.0" ixz="0.0"
                 iyy="0.001" iyz="0.0"
                 izz="0.001" />
      </inertial>
    </link>

    <joint name="caster_front_joint" type="fixed">
      <parent link="base_link"/>
      <child link="caster_front_link"/>
      <origin xyz="0.115 0.0 0.007" rpy="-1.57 0 0"/>
    </joint>
    <link name="caster_front_link">
      <collision>
        <geometry>
          <cylinder length="0.0176" radius="0.017"/>
        </geometry>
        <origin rpy="0 0 0" xyz="0 0 0"/>
      </collision>
      <inertial>
        <mass value="0.01" />
        <origin xyz="0 0 0" />
        <inertia ixx="0.001" ixy="0.0" ixz="0.0"
                 iyy="0.001" iyz="0.0"
                 izz="0.001" />
      </inertial>
    </link>

    <joint name="caster_back_joint" type="fixed">
      <parent link="base_link"/>
      <child link="caster_back_link"/>
      <origin xyz="-0.135 0.0 0.009" rpy="-1.57 0 0"/>
    </joint>
    <link name="caster_back_link">
      <collision>
        <geometry>
          <cylinder length="0.0176" radius="0.017"/>
        </geometry>
        <origin rpy="0 0 0" xyz="0 0 0"/>
      </collision>
      <inertial>
        <mass value="0.01" />
        <origin xyz="0 0 0" />
        <inertia ixx="0.001" ixy="0.0" ixz="0.0"
                 iyy="0.001" iyz="0.0"
                 izz="0.001" />
      </inertial>
    </link>

    <!-- Kobuki's sensors -->
    <joint name="gyro_joint" type="fixed">
      <axis xyz="0 1 0"/>
      <origin xyz="0.056 0.062 0.0202" rpy="0 0 0"/>
      <parent link="base_link"/>
      <child link="gyro_link"/>
    </joint>
    <link name="gyro_link">
      <inertial>
        <mass value="0.001"/>
        <origin xyz="0 0 0" rpy="0 0 0"/>
        <inertia ixx="0.0001" ixy="0" ixz="0"
                 iyy="0.000001" iyz="0"
                 izz="0.0001"/>
      </inertial>
    </link>

    <joint name="cliff_sensor_left_joint" type="fixed">
      <origin xyz="0.08734 0.13601 0.0214" rpy="0 1.57 0" />
      <parent link="base_link"/>
      <child link="cliff_sensor_left_link" />
    </joint>
    <link name="cliff_sensor_left_link">
      <inertial>
        <mass value="0.0001" />
        <origin xyz="0 0 0" />
        <inertia ixx="0.0001" ixy="0.0" ixz="0.0"
                 iyy="0.0001" iyz="0.0"
                 izz="0.0001" />
      </inertial>
    </link>

    <joint name="cliff_sensor_right_joint" type="fixed">
      <origin xyz="0.085 -0.13601 0.0214" rpy="0 1.57 0" />
      <parent link="base_link"/>
      <child link="cliff_sensor_right_link" />
    </joint>
    <link name="cliff_sensor_right_link">
      <inertial>
        <mass value="0.0001" />
        <origin xyz="0 0 0" />
        <inertia ixx="0.0001" ixy="0.0" ixz="0.0"
                 iyy="0.0001" iyz="0.0"
                 izz="0.0001" />
      </inertial>
    </link>

    <joint name="cliff_sensor_front_joint" type="fixed">
      <origin xyz="0.156 0.00 0.0214" rpy="0 1.57 0" />
      <parent link="base_link"/>
      <child link="cliff_sensor_front_link" />
    </joint>
    <link name="cliff_sensor_front_link">
      <inertial>
        <mass value="0.0001" />
        <origin xyz="0 0 0" />
        <inertia ixx="0.0001" ixy="0.0" ixz="0.0"
                 iyy="0.0001" iyz="0.0"
                 izz="0.0001" />
      </inertial>
    </link>




    <!-- phantomx_pincher_arm macro  -->
  <joint name="arm_base_joint" type="fixed">
    <origin rpy="0 0 0" xyz=".1524 0 0.508"/>
    <parent link="base_link"/>
    <child link="arm_base_link"/>
  </joint>
  <link name="arm_base_link">
    <visual>
      <origin rpy="0 0 0" xyz="0 0 0"/>
      <geometry>
        <mesh filename="package://phantomx_pincher_arm_description/meshes/PincherBase.stl" scale="1.0 1.0 1.0"/>
      </geometry>
    </visual>
    <collision>
      <origin rpy="0 0 0" xyz="0 0 0"/>
      <geometry>
        <mesh filename="package://phantomx_pincher_arm_description/meshes/PincherBase.stl" scale="1.0 1.0 1.0"/>
      </geometry>
    </collision>
  </link>
  
  <joint name="arm_shoulder_pan_joint" type="revolute">
    <origin rpy="0 0 0" xyz="0 0 0.020"/>
    <axis xyz="0 0 1"/>
    <limit effort="6" lower="-2.617" upper="2.617" velocity="1.571"/>
    <dynamics friction="0.13"/>
    <parent link="arm_base_link"/>
    <child link="arm_shoulder_pan_link"/>
  </joint>
  <link name="arm_shoulder_pan_link">
    <visual>
      <origin rpy="0 0 0" xyz="0 0 0"/>
      <geometry>
        <mesh filename="package://phantomx_pincher_arm_description/meshes/F2Bracket.stl" scale="1.0 1.0 1.0"/>
      </geometry>
    </visual>
    <collision>
      <origin rpy="0 0 0" xyz="0 0 0"/>
      <geometry>
        <mesh filename="package://phantomx_pincher_arm_description/meshes/F2Bracket.stl" scale="1.0 1.0 1.0"/>
      </geometry>
    </collision>
  </link>
 
  <joint name="arm_bicep_joint" type="revolute">
    <origin rpy="0 0 0" xyz="0 0 0.027"/>
    <axis xyz="0 1 0"/>
    <limit effort="6" lower="-2.3" upper="2.3" velocity="1.571"/>
    <dynamics friction="0.13"/>
    <parent link="arm_shoulder_pan_link"/>
    <child link="arm_bicep_link"/>
  </joint>
  <link name="arm_bicep_link">
    <visual>
      <origin rpy="0 0 0" xyz=" 0 0 0 "/>
      <geometry>
        <mesh filename="package://phantomx_pincher_arm_description/meshes/PincherBicep.stl" scale="1.0 1.0 1.0"/>
      </geometry>
    </visual>
    <collision>
      <origin rpy="0 0 0" xyz="0.0 0.0 0.0"/>
      <geometry>
        <mesh filename="package://phantomx_pincher_arm_description/meshes/PincherBicep.stl" scale="1.0 1.0 1.0"/>
      </geometry>
    </collision>
  </link>
  
  <joint name="arm_forearm_joint" type="revolute">
    <origin rpy="0 0 0" xyz="0.0325 0 0.104"/>
    <axis xyz="0 -1 0"/>
    <limit effort="6" lower="-2.42" upper="2.38" velocity="1.571"/>
    <dynamics friction="0.13"/>
    <parent link="arm_bicep_link"/>
    <child link="arm_forearm_link"/>
  </joint>
  <link name="arm_forearm_link">
    <visual>
      <origin rpy="0 0 0" xyz=" 0 0 0 "/>
      <geometry>
        <mesh filename="package://phantomx_pincher_arm_description/meshes/PincherForeArm.stl" scale="1.0 1.0 1.0"/>
      </geometry>
    </visual>
    <collision>
      <origin rpy="0 0 0" xyz="0.0 0.0 0.0"/>
      <geometry>
        <mesh filename="package://phantomx_pincher_arm_description/meshes/PincherForeArm.stl" scale="1.0 1.0 1.0"/>
      </geometry>
    </collision>
  </link>
  
  <joint name="arm_wrist_flex_joint" type="revolute">
    <origin rpy="0 0 0" xyz="0.104 0 0"/>
    <axis xyz="0 -1 0"/>
    <limit effort="6" lower="-1.72" upper="1.68" velocity="1.571"/>
    <dynamics friction="0.13"/>
    <parent link="arm_forearm_link"/>
    <child link="arm_wrist_flex_link"/>
  </joint>
  <link name="arm_wrist_flex_link">
    <visual>
      <origin rpy="0 0 0" xyz=" 0 0 0 "/>
      <geometry>
        <mesh filename="package://phantomx_pincher_arm_description/meshes/PincherWristGripper.stl" scale="1.0 1.0 1.0"/>
      </geometry>
    </visual>
    <collision>
      <origin rpy="0 0 0" xyz="0.0 0.0 0.0"/>
      <geometry>
        <mesh filename="package://phantomx_pincher_arm_description/meshes/PincherWristGripper.stl" scale="1.0 1.0 1.0"/>
      </geometry>
    </collision>
  </link>
  
  <!-- gripper_link -->
  <joint name="gripper_link_joint" type="revolute">
    <origin rpy="0 0 0" xyz="0.110 0 0"/>
    <parent link="arm_wrist_flex_link"/>
    <child link="gripper_link"/>
    <limit effort="6" lower="-3.14" upper="3.14" velocity="1"/>
    <axis xyz="1 0 0"/>
  </joint>
  <link name="gripper_link">
  </link>

    <!-- gripper joint -->
    <!-- Finger 1 --> 
    <joint name="gripper_joint" type="prismatic">
      <origin xyz="0.070 0 0" rpy="0 0 0"/>
      <axis xyz="0 1 0"/>
      <limit effort="30" velocity="0.5" lower="0.002" upper="0.032"/>
      <parent link="arm_wrist_flex_link"/>
      <child link="gripper_active_link"/>
    </joint> 



    <link name="gripper_active_link">
      <inertial>
        <!-- TODO: This inertial field needs doesn't contain reliable data!! -->
        <mass value="0.01"/>
        <origin xyz="0 0 0" rpy="0 0 0"/>
        <inertia ixx="0.000001" ixy="0.0" ixz="0.0"
                 iyy="0.000001" iyz="0.0"
                 izz="0.000001"/>
      </inertial>
      <visual>
        <geometry>
          <mesh filename="package://phantomx_pincher_arm_description/meshes/PincherFinger.stl" scale="1.0 1.0 1.0"/>
        </geometry>
      </visual>
      <collision>
        <geometry>
          <mesh filename="package://phantomx_pincher_arm_description/meshes/PincherFinger.stl" scale="1.0 1.0 1.0"/>
        </geometry>
      </collision>
    </link>
     
    <!-- Finger 2 --> 
    <!-- Note: currently static but should be a Mimic of Finger 1 -->
    <joint name="gripper2_joint" type="fixed">
      <origin xyz="0.070 -0.016 0" rpy="3.14159 0 0"/>
      <parent link="arm_wrist_flex_link"/>
      <child link="gripper_active2_link"/>
    </joint>  

    <link name="gripper_active2_link">
      <inertial>
        <!-- TODO: This inertial field needs doesn't contain reliable data!! -->
        <mass value="0.01"/>
        <origin xyz="0 0 0" rpy="3.14159 0 0"/>
        <inertia ixx="0.000001" ixy="0.0" ixz="0.0"
                 iyy="0.000001" iyz="0.0"
                 izz="0.000001"/>
      </inertial>
      <visual>
        <geometry>
          <mesh filename="package://phantomx_pincher_arm_description/meshes/PincherFinger.stl" scale="1.0 1.0 1.0"/>
        </geometry>
      </visual>
      <collision>
        <geometry>
          <mesh filename="package://phantomx_pincher_arm_description/meshes/PincherFinger.stl" scale="1.0 1.0 1.0"/>
        </geometry>
      </collision>
    </link>
    <!-- end -->





    <!-- pole -->
    <joint name="pole_bottom_1_joint" type="fixed">
      <origin xyz=".12 .08 .1" rpy="0 0 0"/>
      <parent link="base_link"/>
      <child link="pole_bottom_1_link"/>
    </joint>
    <link name="pole_bottom_1_link">
      <visual>
        <origin xyz="0 0 0" rpy="0 0 0"/>
        <geometry>
          <mesh filename="package://turtlebot_description/meshes/stacks/hexagons/pole_bottom.dae"/>
        </geometry>
      </visual>
      <collision>
        <origin xyz="0 0 0" rpy="0 0 0"/>
        <geometry>
          <cylinder length="0.0492" radius="0.006"/>
        </geometry>
      </collision>
      <inertial>
        <mass value="0.008"/>
        <origin xyz="0 0 0" rpy="0 0 0"/>
        <inertia ixx="0.000001686" ixy="0.0" ixz="0.0"
                 iyy="0.000001686" iyz="0.0"
                 izz="0.000000144"/>
      </inertial>
    </link>
    <joint name="pole_bottom_2_joint" type="fixed">
      <origin xyz=".12 -.08 .1" rpy="0 0 0"/>
      <parent link="base_link"/>
      <child link="pole_bottom_2_link"/>
    </joint>
    <link name="pole_bottom_2_link">
      <visual>
        <origin xyz="0 0 0" rpy="0 0 0"/>
        <geometry>
          <mesh filename="package://turtlebot_description/meshes/stacks/hexagons/pole_bottom.dae"/>
        </geometry>
      </visual>
      <collision>
        <origin xyz="0 0 0" rpy="0 0 0"/>
        <geometry>
          <cylinder length="0.0492" radius="0.006"/>
        </geometry>
      </collision>
      <inertial>
        <mass value="0.008"/>
        <origin xyz="0 0 0" rpy="0 0 0"/>
        <inertia ixx="0.000001686" ixy="0.0" ixz="0.0"
                 iyy="0.000001686" iyz="0.0"
                 izz="0.000000144"/>
      </inertial>
    </link>

    <joint name="pole_top_1_joint" type="fixed">
      <origin xyz=".055 .12 .19" rpy="0 0 0"/>
      <parent link="base_link"/>
      <child link="pole_top_1_link"/>
    </joint>
    <link name="pole_top_1_link">
      <visual>
        <origin xyz="0 0 0" rpy="0 0 0"/>
        <geometry>
          <mesh filename="package://turtlebot_description/meshes/stacks/hexagons/pole_top.dae"/>
        </geometry>
      </visual>
      <collision>
        <origin xyz="0 0 0" rpy="0 0 0"/>
        <geometry>
          <cylinder length="0.2032" radius="0.006"/>
        </geometry>
      </collision>
      <inertial>
        <mass value="0.060"/>
        <origin xyz="0 0 0"/>
        <inertia ixx="0.000206991" ixy="0.0" ixz="0.0"
                 iyy="0.000206991" iyz="0.0"
                 izz="0.000001080"/>
      </inertial>
    </link>

    <joint name="pole_top_2_joint" type="fixed">
      <origin xyz=".055 -.12 .19" rpy="0 0 0"/>
      <parent link="base_link"/>
      <child link="pole_top_2_link"/>
    </joint>
    <link name="pole_top_2_link">
      <visual>
        <origin xyz="0 0 0" rpy="0 0 0"/>
        <geometry>
          <mesh filename="package://turtlebot_description/meshes/stacks/hexagons/pole_top.dae"/>
        </geometry>
      </visual>
      <collision>
        <origin xyz="0 0 0" rpy="0 0 0"/>
        <geometry>
          <cylinder length="0.2032" radius="0.006"/>
        </geometry>
      </collision>
      <inertial>
        <mass value="0.060"/>
        <origin xyz="0 0 0"/>
        <inertia ixx="0.000206991" ixy="0.0" ixz="0.0"
                 iyy="0.000206991" iyz="0.0"
                 izz="0.000001080"/>
      </inertial>
    </link>

    <joint name="pole_top_3_joint" type="fixed">
      <origin xyz="-.055 .12 .19" rpy="0 0 0"/>
      <parent link="base_link"/>
      <child link="pole_top_3_link"/>
    </joint>
    <link name="pole_top_3_link">
      <visual>
        <origin xyz="0 0 0" rpy="0 0 0"/>
        <geometry>
          <mesh filename="package://turtlebot_description/meshes/stacks/hexagons/pole_top.dae"/>
        </geometry>
      </visual>
      <collision>
        <origin xyz="0 0 0" rpy="0 0 0"/>
        <geometry>
          <cylinder length="0.2032" radius="0.006"/>
        </geometry>
      </collision>
      <inertial>
        <mass value="0.060"/>
        <origin xyz="0 0 0"/>
        <inertia ixx="0.000206991" ixy="0.0" ixz="0.0"
                 iyy="0.000206991" iyz="0.0"
                 izz="0.000001080"/>
      </inertial>
    </link>

    <joint name="pole_top_4_joint" type="fixed">
      <origin xyz="-.055 -.12 .19" rpy="0 0 0"/>
      <parent link="base_link"/>
      <child link="pole_top_4_link"/>
    </joint>
    <link name="pole_top_4_link">
      <visual>
        <origin xyz="0 0 0" rpy="0 0 0"/>
        <geometry>
          <mesh filename="package://turtlebot_description/meshes/stacks/hexagons/pole_top.dae"/>
        </geometry>
      </visual>
      <collision>
        <origin xyz="0 0 0" rpy="0 0 0"/>
        <geometry>
          <cylinder length="0.2032" radius="0.006"/>
        </geometry>
      </collision>
      <inertial>
        <mass value="0.060"/>
        <origin xyz="0 0 0"/>
        <inertia ixx="0.000206991" ixy="0.0" ixz="0.0"
                 iyy="0.000206991" iyz="0.0"
                 izz="0.000001080"/>
      </inertial>
    </link>

    <joint name="plate_bottom_joint" type="fixed">
      <origin xyz="0 0 .127" rpy="0 0 0"/>
      <parent link="base_link"/>
      <child link="plate_bottom_link"/>
    </joint>
    <link name="plate_bottom_link">
      <visual>
        <origin xyz="0 0 0" rpy="0 0 0"/>
        <geometry>
          <mesh filename="package://turtlebot_description/meshes/stacks/hexagons/plate_bottom.dae"/>
        </geometry>
      </visual>
      <collision>
        <origin xyz="0 0 0" rpy="0 0 0"/>
        <geometry>
          <cylinder length="0.2032" radius="0.006"/>
        </geometry>
      </collision>
      <inertial>
        <mass value="0.060"/>
        <origin xyz="0 0 0"/>
        <inertia ixx="0.000206991" ixy="0.0" ixz="0.0"
                 iyy="0.000206991" iyz="0.0"
                 izz="0.000001080"/>
      </inertial>
    </link>
    <joint name="plate_middle_joint" type="fixed">
      <origin xyz="0 0 .1905" rpy="0 0 0"/>
      <parent link="base_link"/>
      <child link="plate_middle_link"/>
    </joint>
    <link name="plate_middle_link">
      <visual>
        <origin xyz="0 0 0" rpy="0 0 0"/>
        <geometry>
          <mesh filename="package://turtlebot_description/meshes/stacks/hexagons/plate_bottom.dae"/>
        </geometry>
      </visual>
      <collision>
        <origin xyz="0 0 0" rpy="0 0 0"/>
        <geometry>
          <cylinder length="0.2032" radius="0.006"/>
        </geometry>
      </collision>
      <inertial>
        <mass value="0.060"/>
        <origin xyz="0 0 0"/>
        <inertia ixx="0.000206991" ixy="0.0" ixz="0.0"
                 iyy="0.000206991" iyz="0.0"
                 izz="0.000001080"/>
      </inertial>
    </link>

    
    <joint name="plate_top_joint" type="fixed">
      <origin xyz="0 0 .29" rpy="0 0 0"/>
      <parent link="base_link"/>
      <child link="plate_top_link"/>
    </joint>
    <link name="plate_top_link">
      <visual>
        <origin xyz="0 0 0" rpy="0 0 0"/>
        <geometry>
          <mesh filename="package://turtlebot_description/meshes/stacks/hexagons/plate_bottom.dae"/>
        </geometry>
      </visual>
      <collision>
        <origin xyz="0 0 0" rpy="0 0 0"/>
        <geometry>
          <cylinder length="0.2032" radius="0.006"/>
        </geometry>
      </collision>
      <inertial>
        <mass value="0.060"/>
        <origin xyz="0 0 0"/>
        <inertia ixx="0.000206991" ixy="0.0" ixz="0.0"
                 iyy="0.000206991" iyz="0.0"
                 izz="0.000001080"/>
      </inertial>
    </link>

    <!-- camera poles -->
    <joint name="pole_camera_joint" type="fixed">
      <origin xyz="0 0 .508" rpy="0 -.523 0"/>
      <parent link="base_link"/>
      <child link="pole_camera_link"/>
    </joint>
    <link name="pole_camera_link">
      <visual>
        <origin xyz="0 0 0" rpy="0 0 0"/>
        <geometry>
          <mesh filename="package://turtlebot_description/meshes/stacks/hexagons/pole_top.dae"/>
        </geometry>
      </visual>
      <collision>
        <origin xyz="0 0 0" rpy="0 0 0"/>
        <geometry>
          <cylinder length="0.2032" radius="0.006"/>
        </geometry>
      </collision>
      <inertial>
        <mass value="0.060"/>
        <origin xyz="0 0 0"/>
        <inertia ixx="0.000206991" ixy="0.0" ixz="0.0"
                 iyy="0.000206991" iyz="0.0"
                 izz="0.000001080"/>
      </inertial>
    </link>

    <!-- camera -->
    <joint name="camera_rgb_joint" type="fixed">
      <origin xyz="-.1778 0 1.016"
              rpy="0 .786 0"/>
      <parent link="base_link"/>
      <child link="camera_rgb_frame" />
    </joint>
    <link name="camera_rgb_frame"/>

    <joint name="camera_rgb_optical_joint" type="fixed">
      <origin xyz="0 0 0" rpy="-1.57 0 -1.57" />
      <parent link="camera_rgb_frame" />
      <child link="camera_rgb_optical_frame" />
    </joint>
    <link name="camera_rgb_optical_frame"/>

    <joint name="camera_joint" type="fixed">
      <origin xyz="0 -.0125 0"
              rpy="0 0 0"/>
      <parent link="camera_rgb_frame"/>
      <child link="camera_link"/>
    </joint>
    <link name="camera_link">
      <visual>
        <origin xyz="-0.04 0.02 -0.01" rpy="-1.57 0 -1.57"/>
        <geometry>
          <mesh filename="package://turtlebot_description/meshes/sensors/astra.dae" scale="1 1 1"/>
        </geometry>
      </visual>
      <collision>
        <origin xyz="0.0 0.0 0.0" rpy="0 0 0" />
        <geometry>
        <box size="0.0400 0.1650 0.0300"/>
      </geometry>
      </collision>
      <inertial>
        <mass value="0.564" />
        <origin xyz="0 0 0" />
        <inertia ixx="0.003881243" ixy="0.0" ixz="0.0"
                 iyy="0.000498940" iyz="0.0"
                 izz="0.003879257" />
      </inertial>
    </link>

    <joint name="camera_depth_joint" type="fixed">
      <origin xyz="0 .025 0" rpy="0 0 0" />
      <parent link="camera_rgb_frame" />
      <child link="camera_depth_frame" />
    </joint>
    <link name="camera_depth_frame"/>

    <joint name="camera_depth_optical_joint" type="fixed">
      <origin xyz="0 0 0" rpy="-1.57 0 -1.57" />
      <parent link="camera_depth_frame" />
      <child link="camera_depth_optical_frame" />
    </joint>
    <link name="camera_depth_optical_frame"/>


    
</robot>
